2021-04-18 22:37:11,124 - teradata.udaexec - INFO - Initializing UdaExec...
2021-04-18 22:37:11,124 - teradata.udaexec - INFO - Reading config files: ['/etc/udaexec.ini: Not Found', '/Users/pravashpanigrahi/udaexec.ini: Not Found', '/Users/pravashpanigrahi/PycharmProjects/python-example/python_db_connector/db_query_into_pandas_dataframe/udaexec.ini: Not Found']
2021-04-18 22:37:11,124 - teradata.udaexec - INFO - Found run number file: "/Users/pravashpanigrahi/PycharmProjects/python-example/python_db_connector/db_query_into_pandas_dataframe/.runNumber"
2021-04-18 22:37:11,124 - teradata.udaexec - INFO - Cleaning up log files older than 90 days.
2021-04-18 22:37:11,124 - teradata.udaexec - INFO - Removed 0 log files.
2021-04-18 22:37:12,150 - teradata.udaexec - INFO - Checkpoint file not found: /Users/pravashpanigrahi/PycharmProjects/python-example/python_db_connector/db_query_into_pandas_dataframe/td_playground.checkpoint
2021-04-18 22:37:12,151 - teradata.udaexec - INFO - No previous checkpoint found, executing from beginning...
2021-04-18 22:37:12,151 - teradata.udaexec - INFO - Execution Details:
/********************************************************************************
 * Application Name: td_playground
 *          Version: 1.0
 *       Run Number: 20210418223711-20
 *             Host: Pravashs-MacBook-Air.local
 *         Platform: macOS-10.16-x86_64-i386-64bit
 *          OS User: pravashpanigrahi
 *   Python Version: 3.9.0
 *  Python Compiler: Clang 6.0 (clang-600.0.57)
 *     Python Build: ('v3.9.0:9cf6752276', 'Oct  5 2020 11:29:23')
 *  UdaExec Version: 15.10.0.21
 *     Program Name: /Users/pravashpanigrahi/PycharmProjects/python-example/python_db_connector/db_query_into_pandas_dataframe/read_sql_pd_util.py
 *      Working Dir: /Users/pravashpanigrahi/PycharmProjects/python-example/python_db_connector/db_query_into_pandas_dataframe
 *      Git Version: git version 2.24.3 (Apple Git-128)
 *     Git Revision: d70ff71
 *        Git Dirty: True [ M python_db_connector/db_query_into_pandas_dataframe/read_sql_pd_util.py,?? python_db_connector/db_query_into_pandas_dataframe/.runNumber,?? python_db_connector/db_query_into_pandas_dataframe/logs/]
 *          Log Dir: /Users/pravashpanigrahi/PycharmProjects/python-example/python_db_connector/db_query_into_pandas_dataframe/logs
 *         Log File: /Users/pravashpanigrahi/PycharmProjects/python-example/python_db_connector/db_query_into_pandas_dataframe/logs/td_playground.20210418223711-20.log
 *     Config Files: ['/etc/udaexec.ini: Not Found', '/Users/pravashpanigrahi/udaexec.ini: Not Found', '/Users/pravashpanigrahi/PycharmProjects/python-example/python_db_connector/db_query_into_pandas_dataframe/udaexec.ini: Not Found']
 *      Query Bands: ApplicationName=td_playground;Version=1.0;JobID=20210418223711-20;ClientUser=pravashpanigrahi;Production=False;udaAppLogFile=/Users/pravashpanigrahi/PycharmProjects/python-example/python_db_connector/db_query_into_pandas_dataframe/logs/td_playground.20210418223711-20.log;gitRevision=d70ff71;gitDirty=True;UtilityName=PyTd;UtilityVersion=15.10.0.21
********************************************************************************/
2021-04-18 22:37:15,497 - google.auth.compute_engine._metadata - WARNING - Compute Engine Metadata server unavailable onattempt 1 of 3. Reason: timed out
2021-04-18 22:37:18,501 - google.auth.compute_engine._metadata - WARNING - Compute Engine Metadata server unavailable onattempt 2 of 3. Reason: timed out
2021-04-18 22:37:18,502 - google.auth.compute_engine._metadata - WARNING - Compute Engine Metadata server unavailable onattempt 3 of 3. Reason: [Errno 64] Host is down
2021-04-18 22:37:18,502 - google.auth._default - WARNING - Authentication failed using Compute Engine authentication due to unavailable metadata server.
2021-04-18 22:37:24,781 - pandas_gbq.gbq - INFO - 2 out of 2 rows loaded.
2021-04-18 22:37:29,222 - teradata.udaexec - INFO - UdaExec exiting.
