2021-04-18 18:10:56,026 - teradata.udaexec - INFO - Initializing UdaExec...
2021-04-18 18:10:56,026 - teradata.udaexec - INFO - Reading config files: ['/etc/udaexec.ini: Not Found', '/Users/pravashpanigrahi/udaexec.ini: Not Found', '/Users/pravashpanigrahi/PycharmProjects/python-example/python_db_connector/db_query_into_pandas_dataframe/udaexec.ini: Not Found']
2021-04-18 18:10:56,026 - teradata.udaexec - INFO - Found run number file: "/Users/pravashpanigrahi/PycharmProjects/python-example/python_db_connector/db_query_into_pandas_dataframe/.runNumber"
2021-04-18 18:10:56,026 - teradata.udaexec - INFO - Cleaning up log files older than 90 days.
2021-04-18 18:10:56,026 - teradata.udaexec - INFO - Removed 0 log files.
2021-04-18 18:10:56,369 - teradata.udaexec - INFO - Checkpoint file not found: /Users/pravashpanigrahi/PycharmProjects/python-example/python_db_connector/db_query_into_pandas_dataframe/td_playground.checkpoint
2021-04-18 18:10:56,370 - teradata.udaexec - INFO - No previous checkpoint found, executing from beginning...
2021-04-18 18:10:56,370 - teradata.udaexec - INFO - Execution Details:
/********************************************************************************
 * Application Name: td_playground
 *          Version: 1.0
 *       Run Number: 20210418181056-11
 *             Host: Pravashs-MacBook-Air.local
 *         Platform: macOS-10.16-x86_64-i386-64bit
 *          OS User: pravashpanigrahi
 *   Python Version: 3.9.0
 *  Python Compiler: Clang 6.0 (clang-600.0.57)
 *     Python Build: ('v3.9.0:9cf6752276', 'Oct  5 2020 11:29:23')
 *  UdaExec Version: 15.10.0.21
 *     Program Name: /Users/pravashpanigrahi/PycharmProjects/python-example/python_db_connector/db_query_into_pandas_dataframe/read_sql_pd_util.py
 *      Working Dir: /Users/pravashpanigrahi/PycharmProjects/python-example/python_db_connector/db_query_into_pandas_dataframe
 *      Git Version: git version 2.24.3 (Apple Git-128)
 *     Git Revision: d70ff71
 *        Git Dirty: True [ M python_db_connector/db_query_into_pandas_dataframe/read_sql_pd_util.py,?? python_db_connector/db_query_into_pandas_dataframe/.runNumber,?? python_db_connector/db_query_into_pandas_dataframe/logs/]
 *          Log Dir: /Users/pravashpanigrahi/PycharmProjects/python-example/python_db_connector/db_query_into_pandas_dataframe/logs
 *         Log File: /Users/pravashpanigrahi/PycharmProjects/python-example/python_db_connector/db_query_into_pandas_dataframe/logs/td_playground.20210418181056-11.log
 *     Config Files: ['/etc/udaexec.ini: Not Found', '/Users/pravashpanigrahi/udaexec.ini: Not Found', '/Users/pravashpanigrahi/PycharmProjects/python-example/python_db_connector/db_query_into_pandas_dataframe/udaexec.ini: Not Found']
 *      Query Bands: ApplicationName=td_playground;Version=1.0;JobID=20210418181056-11;ClientUser=pravashpanigrahi;Production=False;udaAppLogFile=/Users/pravashpanigrahi/PycharmProjects/python-example/python_db_connector/db_query_into_pandas_dataframe/logs/td_playground.20210418181056-11.log;gitRevision=d70ff71;gitDirty=True;UtilityName=PyTd;UtilityVersion=15.10.0.21
********************************************************************************/
2021-04-18 18:10:56,384 - teradata.udaexec - INFO - Creating connection: {'username': 'dbc', 'password': 'XXXXXX', 'database': 'DBC'}
2021-04-18 18:10:56,385 - teradata.udaexec - ERROR - Uncaught exception
Traceback (most recent call last):
  File "/Users/pravashpanigrahi/PycharmProjects/python-example/python_db_connector/db_query_into_pandas_dataframe/read_sql_pd_util.py", line 48, in <module>
    session = udaExec.connect(
  File "/Users/pravashpanigrahi/PycharmProjects/.python/envs/lib/python3.9/site-packages/teradata/udaexec.py", line 162, in connect
    util.raiseIfNone('method', method)
  File "/Users/pravashpanigrahi/PycharmProjects/.python/envs/lib/python3.9/site-packages/teradata/util.py", line 75, in raiseIfNone
    raise InterfaceError(
teradata.api.InterfaceError: ('INVALID_ARGUMENT', 'Missing value for "method".')
2021-04-18 18:10:56,388 - teradata.udaexec - INFO - UdaExec exiting.
